Workbook

Sheet Posts
A1: LinkedIn Feed Scrape - 1st Connections, Sorted by Latest
A2: Source: linkedin.com/search/results/content (postedBy=1st connections, sortBy=date_posted). Pulled Sept 2026. Engagement = reactions + comments + reposts. Category assigned by keyword heuristic - verify before using. Post Link opens the original LinkedIn post.
A4: Author | B4: Headline / Role | C4: Post Age | D4: Reactions | E4: Comments | F4: Reposts | G4: Total Engagement | H4: Category | I4: Language | J4: Post Link | K4: Content Snippet
A5: Andreina Isabel Díaz Ravelo | B5: Head of Talent Growth & Operations | C5: 1h | D5: 4 | E5: 0 | F5: 0 | G5: =D5+E5+F5 -> 4 | H5: hiring | I5: Spanish | J5: https://lnkd.in/p/gCrdEkRu | K5: Andreina Isabel Díaz Ravelo • 1st Head of Talent Growth & Operations 1h • Buscamos un(a) Senior Talent IT Specialist para sumarse a nuestro equipo y liderar procesos de selección de principio a fin. Serás protagonista en la búsqueda de talento tecnológico para clientes de distintas industrias, trabajando con perfiles altamente especializados en desarrollo de software, cloud, datos, arquitectura, ciberseguridad y más. Si eres de quienes no esperan que los candidatos postulen, sino que salen a encontrarlos, esta oportunidad es para ti. ¿Cuáles serán tus funciones?😎 - Liderar procesos d
A6: BelisariosCorpTech . | B6: CEO | C6: 1h | D6: 1 | E6: 0 | F6: 1 | G6: =D6+E6+F6 -> 2 | H6: other | I6: Spanish | J6: https://lnkd.in/p/gTGeaBU2 | K6: BelisariosCorpTech . • 1st CEO 1h • "IMPRESORAS DE PEQUEÑO Y GRAN FORMATO A TÚ DISPOSICIÓN" Somos BelisariosCorpTech, "Una organización cuyo modelo de negocio exponencial le permite empoderar gente, empresas e impulsar el desarrollo de la actividad económica nacional. (INFRAESTRUCTURA TECNOLÓGICA EMPRESARIAL) "Servidores(DL360,DL380,R540, R760xs, r660xs, Ml110, Ml30) laptops (Hp, Lenovo, dell, Gateway, apple , Acer, Asus, msi) switches (24-48Ports) Monitores, Impresoras, storage Powervoult ME5012 y otros en líneas generales, Radios Intrìnsecamente seguros, Video Beams, Pc, all in on
A7: Ariana Sol Geraci | B7: Psychologist / Global Recruiter 🚀💻 | C7: 2h | D7: 0 | E7: 0 | F7: 0 | G7: =D7+E7+F7 -> 0 | H7: thought_leadership | I7: Spanish | J7: https://lnkd.in/p/gH-VbRt8 | K7: Ariana Sol Geraci • 1st Psychologist / Global Recruiter 🚀💻 2h • Edited • Hola red!👋 Está creciendo nuestro equipo en South, y estamos buscando un/a #𝗖𝗼𝗽𝘆𝘄𝗿𝗶𝘁𝗲𝗿 🚀 📍 100% remoto desde LATAM 🕐 Full-time, de lunes a viernes. El puesto requiere al menos 6 horas de superposición diaria con nuestro equipo en Argentina (9:00 AM–6:00 PM, hora de Argentina). 🎯 𝗤𝘂𝗲́ 𝗯𝘂𝘀𝗰𝗮𝗺𝗼𝘀 • Experiencia comprobable en copywriting B2B, marketing de contenidos o contenido SEO. • Sólidas habilidades de redacción B2B y excelente nivel de inglés escrito, con capacidad para simplificar t
A8: Ashley Sullivan | B8: Talent Acquisition Partner-Nursing | C8: 3h | D8: 1 | E8: 0 | F8: 0 | G8: =D8+E8+F8 -> 1 | H8: other | I8: English | J8: https://lnkd.in/p/gD8dacUF | K8: Ashley Sullivan • 1st Talent Acquisition Partner-Nursing 3h • 💜 Calling experienced Critical Care nurses ready to take the next step in their leadership journey! Novant Health Huntersville Medical Center is looking for an Assistant Nurse Manager (ANM) to join our Medical ICU team. This is an exciting opportunity to support a talented team while making an impact through clinical leadership, mentorship, collaboration, and exceptional patient care. ✨ Relocation assistance available ✨ ANM shift incentive available ✨ Flexible schedule between 5:00 PM–3:00 AM ✨ Four 10-hour shifts per wee
A9: Rocío García Algora | B9: Posicionamiento de marca en LinkedIn para especialistas B2B cuyo reconocimiento no refleja su experiencia.| Haz visible el valor que te hace diferente y conviértelo en una marca que el mercado entiende, recuerda y elige. | C9: 6h | D9: 8 | E9: 11 | F9: 0 | G9: =D9+E9+F9 -> 19 | H9: other | I9: Spanish | J9: https://lnkd.in/p/gxBy4CPj | K9: Rocío García Algora • 1st Posicionamiento de marca en LinkedIn para especialistas B2B cuyo reconocimiento no refleja su experiencia.| Haz visible el valor que te hace diferente y conviértelo en una marca que el mercado entiende, recuerda y elige. 6h • 3 dudas sobre tu cliente ideal que pueden estar frenando tu posicionamiento, y tu cartera 🤌 1. "Si segmento mucho, pierdo oportunidades" Las oportunidades las pierdes cuando no generas un mensaje que conecta con tu cliente Piensa en la última ocasión que has necesitado resolver un asunto complejo: ¿elegiste al generalista o a algu
A10: Deisa González | B10: Deisa González: Director en Miradas Empresariales / Consultor empresarial / Psicóloga FPV: 4532. Magíster en Relaciones industriales y laborales . | C10: 14h | D10: 0 | E10: 0 | F10: 0 | G10: =D10+E10+F10 -> 0 | H10: hiring | I10: Spanish | J10: https://lnkd.in/p/gBgN_rgv | K10: Deisa González • 1st Deisa González: Director en Miradas Empresariales / Consultor empresarial / Psicóloga FPV: 4532. Magíster en Relaciones industriales y laborales . 14h • Para empresa manufacturera de soluciones de empaque(sector farmacéutico y/o cosméticos), buscamos: Gerente de Nuevos Negocios Con sólida orientación comercial, comprensión de procesos industriales y capacidad para innovar y liderar proyectos técnicos de desarrollo de empaques desde la identificación de la oportunidad hasta su validación e incorporación comercial. Reportando directamente al Gerente General del neg
A11: BelisariosCorpTech . | B11: CEO | C11: 20h | D11: 1 | E11: 0 | F11: 1 | G11: =D11+E11+F11 -> 2 | H11: other | I11: Spanish | J11: https://lnkd.in/p/gKA-Pb56 | K11: BelisariosCorpTech . • 1st CEO 20h • “VAMOS DE TÚ MANO EN LOS PROYECTOS DE MODERNIZACIÓN" Somos BelisariosCorpTech, "Una organización cuyo modelo de negocio exponencial le permite empoderar gente, empresas e impulsar el desarrollo de la actividad económica nacional. (INFRAESTRUCTURA TECNOLÓGICA EMPRESARIAL) "Servidores(DL360,DL380,R550 , R760xs, R660xs, R360), Licenciamiento, laptops (Hp, Lenovo, dell, Gateway, apple , Acer, Asus, msi) switches (24-48Ports) Monitores, Impresoras, storage Powervoult ME5012 y otros en líneas generales, Radios Intrìnsecamente seguros, Video Beams, Pc, a
A12: Iván Ramos | B12: Sales Manager at OCTOPUS Agencia SEO | C12: 1d | D12: 0 | E12: 0 | F12: 0 | G12: =D12+E12+F12 -> 0 | H12: other | I12: Spanish | J12: https://lnkd.in/p/gWnUyKAu | K12: Iván Ramos • 1st Sales Manager at OCTOPUS Agencia SEO Book an appointment 1d • Tu agencia SEO te dice "vamos bien" cada mes... pero tu flujo de caja dice otra cosa Hay 7 KPIs que te dicen si tu agencia sabe lo que hace Los juntamos en un ebook Incluye la tasa a la que crece un sitio en Google sin que nadie lo toque (Si tu agencia no la supera, está cobrando por nada) Comenta "KPI" y te lo mando por DM Por fa, asegúrate de que estemos conectados, si no, LinkedIn no me deja escribirte O si prefieres que revisemos tu caso en tiempo real: https://lnkd.in/ezvC9qSY … more Show translat
A13: Álvaro Peña de Luna | B13: coCEO, Head of SEO e IA de iSocialWeb, Growwer, Mencoro.com y Vuela.ai🎙️Podcaster de IA en El Test de Turing | C13: 1d | D13: 40 | E13: 12 | F13: 3 | G13: =D13+E13+F13 -> 55 | H13: other | I13: Spanish | J13: https://lnkd.in/p/gpCZF5i2 | K13: Álvaro Peña de Luna • 1st coCEO, Head of SEO e IA de iSocialWeb, Growwer, Mencoro.com y Vuela.ai🎙️Podcaster de IA en El Test de Turing 1d • 😈 HACKEANDO Google Business Profile: Alguien puede poner su teléfono en la ficha de Google de tu negocio. Sin tocar tu ficha. Lo hace con una foto generada con IA. Y Google la muestra arriba, casi como si fuera tu imagen de portada. El caso está documentado esta semana. Y lo que acabó resolviéndolo no fue el formulario de denuncia. Lo contó Naomi Stevens en un grupo de LinkedIn, y de ahí lo recogió Sam Sarsten. Cliente suyo, empresa de tejados.
A14: Lina Garcia | B14: Costeo y Pricing | ABC Logística | Preparamos tus pedidos para Retail, Distribuidores, Marketplaces, Ecommerce | 3PL México | C14: 2d | D14: 28 | E14: 1 | F14: 0 | G14: =D14+E14+F14 -> 29 | H14: other | I14: Spanish | J14: https://lnkd.in/p/gF5by3Jq | K14: Lina Garcia • 1st Costeo y Pricing | ABC Logística | Preparamos tus pedidos para Retail, Distribuidores, Marketplaces, Ecommerce | 3PL México 2d • Entras a LinkedIn y entre varios mensajes automatizados ves uno como este. Una vendedora que se interesa, que está a dispuesta a aprender, que quiere dar algo a cambio “puedo ir a poner etiquetas o algo” (esto probablemente no se pueda por temas de relación laboral) pero eso no importa, vale mucho la intención. Al final, si Brenda va a visitarnos y me deja su portafolio de transportes lo recibiré con gusto, porque además, estoy segura qu
A15: Mariam Veiga | B15: Marca personal como fuerza comercial | Para directivos y emprendedores que quieren que su nombre abra puertas y genere oportunidades de negocio | +750 proyectos | C15: 2d | D15: 23 | E15: 42 | F15: 0 | G15: =D15+E15+F15 -> 65 | H15: other | I15: Spanish | J15: https://lnkd.in/p/gA46JcU5 | K15: Mariam Veiga • 1st Marca personal como fuerza comercial | Para directivos y emprendedores que quieren que su nombre abra puertas y genere oportunidades de negocio | +750 proyectos Book an appointment 2d • LinkedIn ha dejado de quererme. He intentado unas 5 veces compartir un post, pero nada. Que no. No quiere. ¿Alguien puede decirme qué puede estar pasando? PD: y sin embargo, esto, sí me deja... … more Show translation Mariam Veiga and 22 others reacted Mariam Veiga and 22 others 42 comments 42 comments Like Comment Repost Send
A16: BelisariosCorpTech . | B16: CEO | C16: 22h | D16: 1 | E16: 0 | F16: 3 | G16: =D16+E16+F16 -> 4 | H16: other | I16: Spanish | J16: https://lnkd.in/p/gcJ-zvgm | K16: BelisariosCorpTech . • 1st CEO 22h • "LAPTOPS IDEALES PARA TÚ ORGANIZACIÓN " Somos BelisariosCorpTech, "Una organización cuyo modelo de negocio exponencial le permite empoderar gente, empresas e impulsar el desarrollo de la actividad económica nacional. (INFRAESTRUCTURA TECNOLÓGICA EMPRESARIAL) "Servidores(DL360,DL380,R550 , R760xs, R660xs, R360), Licenciamiento, laptops (Hp, Lenovo, dell, Gateway, apple , Acer, Asus, msi) switches (24-48Ports) Monitores, Impresoras, storage Powervoult ME5012 y otros en líneas generales, Radios Intrìnsecamente seguros, Video Beams, Pc, all in one, ce
... A151: Deisa González | B151: Deisa González: Director en Miradas Empresariales / Consultor empresarial / Psicóloga FPV: 4532. Magíster en Relaciones industriales y laborales . | C151: 1mo | D151: 1 | E151: 0 | F151: 0 | G151: =D151+E151+F151 -> 1 | H151: hiring | I151: Spanish | J151: https://lnkd.in/p/g9APSbHN | K151: Deisa González • 1st Deisa González: Director en Miradas Empresariales / Consultor empresarial / Psicóloga FPV: 4532. Magíster en Relaciones industriales y laborales . 1mo • Para empresa manufacturera de soluciones de empaque(sector farmacéutico y/o cosméticos), buscamos: Gerente de Nuevos Negocios 🎯 Con sólida orientación comercial, comprensión de procesos industriales y capacidad para innovar y liderar proyectos técnicos de desarrollo de empaques desde la identificación de la oportunidad hasta su validación e incorporación comercial. Reportando directamente al Gerente General
B153: =COUNTA(A5:A151) & " posts" -> 147 posts | C153: TOTALS | D153: =SUM(D5:D151) -> 3547 | E153: =SUM(E5:E151) -> 1920 | F153: =SUM(F5:F151) -> 135 | G153: =SUM(G5:G151) -> 5602

Sheet Category Summary
A1: Engagement by Content Category
A2: All figures pull live from the Posts sheet via SUMIF/COUNTIF/AVERAGEIF - edit Posts and these update.
A4: Category | B4: Post Count | C4: Total Engagement | D4: Avg Engagement / Post | E4: Share of Posts
A5: Hiring / Recruiting | B5: =COUNTIF(Posts!$H$5:$H$151,"hiring") -> 37 | C5: =SUMIF(Posts!$H$5:$H$151,"hiring",Posts!$G$5:$G$151) -> 1661 | D5: =IFERROR(C5/B5,0) -> 44.891892 | E5: =B5/147 -> 0.25170068
A6: Lead-gen / Coaching bait | B6: =COUNTIF(Posts!$H$5:$H$151,"leadgen_coaching") -> 7 | C6: =SUMIF(Posts!$H$5:$H$151,"leadgen_coaching",Posts!$G$5:$G$151) -> 13 | D6: =IFERROR(C6/B6,0) -> 1.8571429 | E6: =B6/147 -> 0.047619048
A7: Thought leadership / Opinion | B7: =COUNTIF(Posts!$H$5:$H$151,"thought_leadership") -> 21 | C7: =SUMIF(Posts!$H$5:$H$151,"thought_leadership",Posts!$G$5:$G$151) -> 1127 | D7: =IFERROR(C7/B7,0) -> 53.666667 | E7: =B7/147 -> 0.14285714
A8: Company / Product promo | B8: =COUNTIF(Posts!$H$5:$H$151,"company_promo") -> 0 | C8: =SUMIF(Posts!$H$5:$H$151,"company_promo",Posts!$G$5:$G$151) -> 0 | D8: =IFERROR(C8/B8,0) -> 0 | E8: =B8/147 -> 0
A9: Job seeking / Open to work | B9: =COUNTIF(Posts!$H$5:$H$151,"job_seeking") -> 0 | C9: =SUMIF(Posts!$H$5:$H$151,"job_seeking",Posts!$G$5:$G$151) -> 0 | D9: =IFERROR(C9/B9,0) -> 0 | E9: =B9/147 -> 0
A10: Other (updates, misc) | B10: =COUNTIF(Posts!$H$5:$H$151,"other") -> 82 | C10: =SUMIF(Posts!$H$5:$H$151,"other",Posts!$G$5:$G$151) -> 2801 | D10: =IFERROR(C10/B10,0) -> 34.158537 | E10: =B10/147 -> 0.55782313
A11: TOTAL | B11: =SUM(B5:B10) -> 147 | C11: =SUM(C5:C10) -> 5602
A14: Engagement by Post Language
A15: Language assigned by stopword-frequency heuristic on the post snippet (Spanish/English/Portuguese lexicons) - spot-check before treating as ground truth.
A17: Language | B17: Post Count | C17: Total Engagement | D17: Avg Engagement / Post | E17: Share of Posts
A18: Spanish | B18: =COUNTIF(Posts!$I$5:$I$151,"Spanish") -> 110 | C18: =SUMIF(Posts!$I$5:$I$151,"Spanish",Posts!$G$5:$G$151) -> 4292 | D18: =IFERROR(C18/B18,0) -> 39.018182 | E18: =B18/147 -> 0.74829932
A19: English | B19: =COUNTIF(Posts!$I$5:$I$151,"English") -> 34 | C19: =SUMIF(Posts!$I$5:$I$151,"English",Posts!$G$5:$G$151) -> 1166 | D19: =IFERROR(C19/B19,0) -> 34.294118 | E19: =B19/147 -> 0.23129252
A20: Portuguese | B20: =COUNTIF(Posts!$I$5:$I$151,"Portuguese") -> 3 | C20: =SUMIF(Posts!$I$5:$I$151,"Portuguese",Posts!$G$5:$G$151) -> 144 | D20: =IFERROR(C20/B20,0) -> 48 | E20: =B20/147 -> 0.020408163
A21: TOTAL | B21: =SUM(B18:B20) -> 147 | C21: =SUM(C18:C20) -> 5602

Sheet Author Leaderboard
A1: Engagement by Author (all posts in sample)
A2: Total Engagement and Post Count pull live from the Posts sheet via SUMIF/COUNTIF.
A4: Author | B4: Posts in Sample | C4: Total Engagement | D4: Avg Engagement / Post
A5: Amarilis Gonzalez | B5: =COUNTIF(Posts!$A$5:$A$151,"Amarilis Gonzalez") -> 11 | C5: =SUMIF(Posts!$A$5:$A$151,"Amarilis Gonzalez",Posts!$G$5:$G$151) -> 1630 | D5: =IFERROR(C5/B5,0) -> 148.18182
A6: Monika Saleta, DrBA | B6: =COUNTIF(Posts!$A$5:$A$151,"Monika Saleta, DrBA") -> 12 | C6: =SUMIF(Posts!$A$5:$A$151,"Monika Saleta, DrBA",Posts!$G$5:$G$151) -> 1000 | D6: =IFERROR(C6/B6,0) -> 83.333333
A7: Maxence Marius | B7: =COUNTIF(Posts!$A$5:$A$151,"Maxence Marius") -> 2 | C7: =SUMIF(Posts!$A$5:$A$151,"Maxence Marius",Posts!$G$5:$G$151) -> 719 | D7: =IFERROR(C7/B7,0) -> 359.5
A8: Raul Montalvo | B8: =COUNTIF(Posts!$A$5:$A$151,"Raul Montalvo") -> 5 | C8: =SUMIF(Posts!$A$5:$A$151,"Raul Montalvo",Posts!$G$5:$G$151) -> 401 | D8: =IFERROR(C8/B8,0) -> 80.2
A9: Rocío García Algora | B9: =COUNTIF(Posts!$A$5:$A$151,"Rocío García Algora") -> 4 | C9: =SUMIF(Posts!$A$5:$A$151,"Rocío García Algora",Posts!$G$5:$G$151) -> 216 | D9: =IFERROR(C9/B9,0) -> 54
A10: Mariam Veiga | B10: =COUNTIF(Posts!$A$5:$A$151,"Mariam Veiga") -> 3 | C10: =SUMIF(Posts!$A$5:$A$151,"Mariam Veiga",Posts!$G$5:$G$151) -> 177 | D10: =IFERROR(C10/B10,0) -> 59
A11: Ricardo Rincón | B11: =COUNTIF(Posts!$A$5:$A$151,"Ricardo Rincón") -> 3 | C11: =SUMIF(Posts!$A$5:$A$151,"Ricardo Rincón",Posts!$G$5:$G$151) -> 175 | D11: =IFERROR(C11/B11,0) -> 58.333333
A12: Vanessa Brito Montilla | B12: =COUNTIF(Posts!$A$5:$A$151,"Vanessa Brito Montilla") -> 3 | C12: =SUMIF(Posts!$A$5:$A$151,"Vanessa Brito Montilla",Posts!$G$5:$G$151) -> 129 | D12: =IFERROR(C12/B12,0) -> 43
A13: María Rojas | B13: =COUNTIF(Posts!$A$5:$A$151,"María Rojas") -> 1 | C13: =SUMIF(Posts!$A$5:$A$151,"María Rojas",Posts!$G$5:$G$151) -> 101 | D13: =IFERROR(C13/B13,0) -> 101
A14: Álvaro Peña de Luna | B14: =COUNTIF(Posts!$A$5:$A$151,"Álvaro Peña de Luna") -> 2 | C14: =SUMIF(Posts!$A$5:$A$151,"Álvaro Peña de Luna",Posts!$G$5:$G$151) -> 98 | D14: =IFERROR(C14/B14,0) -> 49
A15: Rodolfo Barbosa | B15: =COUNTIF(Posts!$A$5:$A$151,"Rodolfo Barbosa") -> 2 | C15: =SUMIF(Posts!$A$5:$A$151,"Rodolfo Barbosa",Posts!$G$5:$G$151) -> 92 | D15: =IFERROR(C15/B15,0) -> 46
A16: Natalia Montolio | B16: =COUNTIF(Posts!$A$5:$A$151,"Natalia Montolio") -> 5 | C16: =SUMIF(Posts!$A$5:$A$151,"Natalia Montolio",Posts!$G$5:$G$151) -> 81 | D16: =IFERROR(C16/B16,0) -> 16.2
A17: Lorena Alejandra Rodriguez | B17: =COUNTIF(Posts!$A$5:$A$151,"Lorena Alejandra Rodriguez") -> 1 | C17: =SUMIF(Posts!$A$5:$A$151,"Lorena Alejandra Rodriguez",Posts!$G$5:$G$151) -> 74 | D17: =IFERROR(C17/B17,0) -> 74
A18: BelisariosCorpTech . | B18: =COUNTIF(Posts!$A$5:$A$151,"BelisariosCorpTech .") -> 23 | C18: =SUMIF(Posts!$A$5:$A$151,"BelisariosCorpTech .",Posts!$G$5:$G$151) -> 50 | D18: =IFERROR(C18/B18,0) -> 2.173913
A19: Betlem Cardona Devesa | B19: =COUNTIF(Posts!$A$5:$A$151,"Betlem Cardona Devesa") -> 1 | C19: =SUMIF(Posts!$A$5:$A$151,"Betlem Cardona Devesa",Posts!$G$5:$G$151) -> 49 | D19: =IFERROR(C19/B19,0) -> 49
A20: Asdrubal R. Oliveros P. | B20: =COUNTIF(Posts!$A$5:$A$151,"Asdrubal R. Oliveros P.") -> 1 | C20: =SUMIF(Posts!$A$5:$A$151,"Asdrubal R. Oliveros P.",Posts!$G$5:$G$151) -> 49 | D20: =IFERROR(C20/B20,0) -> 49
A21: Zargaam U. | B21: =COUNTIF(Posts!$A$5:$A$151,"Zargaam U.") -> 2 | C21: =SUMIF(Posts!$A$5:$A$151,"Zargaam U.",Posts!$G$5:$G$151) -> 45 | D21: =IFERROR(C21/B21,0) -> 22.5
A22: Fernando P. Maniglia | B22: =COUNTIF(Posts!$A$5:$A$151,"Fernando P. Maniglia") -> 2 | C22: =SUMIF(Posts!$A$5:$A$151,"Fernando P. Maniglia",Posts!$G$5:$G$151) -> 42 | D22: =IFERROR(C22/B22,0) -> 21
A23: Kishalaya Mukhopadhyay | B23: =COUNTIF(Posts!$A$5:$A$151,"Kishalaya Mukhopadhyay") -> 2 | C23: =SUMIF(Posts!$A$5:$A$151,"Kishalaya Mukhopadhyay",Posts!$G$5:$G$151) -> 41 | D23: =IFERROR(C23/B23,0) -> 20.5
A24: Lina Garcia | B24: =COUNTIF(Posts!$A$5:$A$151,"Lina Garcia") -> 1 | C24: =SUMIF(Posts!$A$5:$A$151,"Lina Garcia",Posts!$G$5:$G$151) -> 29 | D24: =IFERROR(C24/B24,0) -> 29
A25: Cristian Albor | B25: =COUNTIF(Posts!$A$5:$A$151,"Cristian Albor") -> 1 | C25: =SUMIF(Posts!$A$5:$A$151,"Cristian Albor",Posts!$G$5:$G$151) -> 29 | D25: =IFERROR(C25/B25,0) -> 29
A26: Jesus Vivas Medina | B26: =COUNTIF(Posts!$A$5:$A$151,"Jesus Vivas Medina") -> 1 | C26: =SUMIF(Posts!$A$5:$A$151,"Jesus Vivas Medina",Posts!$G$5:$G$151) -> 29 | D26: =IFERROR(C26/B26,0) -> 29
A27: Carlos González | B27: =COUNTIF(Posts!$A$5:$A$151,"Carlos González") -> 1 | C27: =SUMIF(Posts!$A$5:$A$151,"Carlos González",Posts!$G$5:$G$151) -> 26 | D27: =IFERROR(C27/B27,0) -> 26
A28: Nakary Mendoza | B28: =COUNTIF(Posts!$A$5:$A$151,"Nakary Mendoza") -> 1 | C28: =SUMIF(Posts!$A$5:$A$151,"Nakary Mendoza",Posts!$G$5:$G$151) -> 25 | D28: =IFERROR(C28/B28,0) -> 25
A29: venus Castellanos | B29: =COUNTIF(Posts!$A$5:$A$151,"venus Castellanos") -> 1 | C29: =SUMIF(Posts!$A$5:$A$151,"venus Castellanos",Posts!$G$5:$G$151) -> 20 | D29: =IFERROR(C29/B29,0) -> 20
A30: Salvador Ramos Lopez | B30: =COUNTIF(Posts!$A$5:$A$151,"Salvador Ramos Lopez") -> 1 | C30: =SUMIF(Posts!$A$5:$A$151,"Salvador Ramos Lopez",Posts!$G$5:$G$151) -> 20 | D30: =IFERROR(C30/B30,0) -> 20
A31: Diego Edgardo Martin Camacho | B31: =COUNTIF(Posts!$A$5:$A$151,"Diego Edgardo Martin Camacho") -> 1 | C31: =SUMIF(Posts!$A$5:$A$151,"Diego Edgardo Martin Camacho",Posts!$G$5:$G$151) -> 20 | D31: =IFERROR(C31/B31,0) -> 20
A32: Katherine Uriarte Ortiz | B32: =COUNTIF(Posts!$A$5:$A$151,"Katherine Uriarte Ortiz") -> 1 | C32: =SUMIF(Posts!$A$5:$A$151,"Katherine Uriarte Ortiz",Posts!$G$5:$G$151) -> 19 | D32: =IFERROR(C32/B32,0) -> 19
A33: Leonardo Manotas Garcés | B33: =COUNTIF(Posts!$A$5:$A$151,"Leonardo Manotas Garcés") -> 2 | C33: =SUMIF(Posts!$A$5:$A$151,"Leonardo Manotas Garcés",Posts!$G$5:$G$151) -> 18 | D33: =IFERROR(C33/B33,0) -> 9
A34: Valeria Seoane Macchiavello | B34: =COUNTIF(Posts!$A$5:$A$151,"Valeria Seoane Macchiavello") -> 1 | C34: =SUMIF(Posts!$A$5:$A$151,"Valeria Seoane Macchiavello",Posts!$G$5:$G$151) -> 17 | D34: =IFERROR(C34/B34,0) -> 17
A35: Ariana Sol Geraci | B35: =COUNTIF(Posts!$A$5:$A$151,"Ariana Sol Geraci") -> 2 | C35: =SUMIF(Posts!$A$5:$A$151,"Ariana Sol Geraci",Posts!$G$5:$G$151) -> 16 | D35: =IFERROR(C35/B35,0) -> 8
A36: Muhammad Ali | B36: =COUNTIF(Posts!$A$5:$A$151,"Muhammad Ali") -> 1 | C36: =SUMIF(Posts!$A$5:$A$151,"Muhammad Ali",Posts!$G$5:$G$151) -> 16 | D36: =IFERROR(C36/B36,0) -> 16
A37: Omar Fuentes Lambouret | B37: =COUNTIF(Posts!$A$5:$A$151,"Omar Fuentes Lambouret") -> 1 | C37: =SUMIF(Posts!$A$5:$A$151,"Omar Fuentes Lambouret",Posts!$G$5:$G$151) -> 13 | D37: =IFERROR(C37/B37,0) -> 13
A38: Sanchit Jain | B38: =COUNTIF(Posts!$A$5:$A$151,"Sanchit Jain") -> 1 | C38: =SUMIF(Posts!$A$5:$A$151,"Sanchit Jain",Posts!$G$5:$G$151) -> 12 | D38: =IFERROR(C38/B38,0) -> 12
A39: Diana Hernández | B39: =COUNTIF(Posts!$A$5:$A$151,"Diana Hernández") -> 1 | C39: =SUMIF(Posts!$A$5:$A$151,"Diana Hernández",Posts!$G$5:$G$151) -> 12 | D39: =IFERROR(C39/B39,0) -> 12
A40: Antonella Ojuez | B40: =COUNTIF(Posts!$A$5:$A$151,"Antonella Ojuez") -> 1 | C40: =SUMIF(Posts!$A$5:$A$151,"Antonella Ojuez",Posts!$G$5:$G$151) -> 10 | D40: =IFERROR(C40/B40,0) -> 10
A41: Deisa González | B41: =COUNTIF(Posts!$A$5:$A$151,"Deisa González") -> 8 | C41: =SUMIF(Posts!$A$5:$A$151,"Deisa González",Posts!$G$5:$G$151) -> 8 | D41: =IFERROR(C41/B41,0) -> 1
...
